[2024-03-28 12:31:39,997] 17 root - INFO - Dataframe Gathered
[2024-03-28 12:31:41,328] 96 werkzeug - INFO - [31m[1mWARNING: This is a development server. Do not use it in a production deployment. Use a production WSGI server instead.[0m
 * Running on all addresses (0.0.0.0)
 * Running on http://127.0.0.1:8000
 * Running on http://192.168.1.37:8000
[2024-03-28 12:31:41,328] 96 werkzeug - INFO - [33mPress CTRL+C to quit[0m
[2024-03-28 12:31:49,127] 96 werkzeug - INFO - 127.0.0.1 - - [28/Mar/2024 12:31:49] "GET / HTTP/1.1" 200 -
[2024-03-28 12:31:49,358] 96 werkzeug - INFO - 127.0.0.1 - - [28/Mar/2024 12:31:49] "[33mGET /static/styles.css HTTP/1.1[0m" 404 -
[2024-03-28 12:31:54,747] 96 werkzeug - INFO - 127.0.0.1 - - [28/Mar/2024 12:31:54] "GET / HTTP/1.1" 200 -
[2024-03-28 12:31:55,112] 96 werkzeug - INFO - 127.0.0.1 - - [28/Mar/2024 12:31:55] "[33mGET /static/styles.css HTTP/1.1[0m" 404 -
[2024-03-28 12:32:09,742] 828 app - ERROR - Exception on /predict [POST]
Traceback (most recent call last):
  File "C:\project\bike_prediction\src\BikeSharePrediction\pipelines\prediction_pipeline.py", line 74, in get_data_as_dataframe
    logging.info('Dataframe Gathered')
AttributeError: module 'src.BikeSharePrediction.logger.logging' has no attribute 'info'

During handling of the above exception, another exception occurred:

Traceback (most recent call last):
  File "C:\project\bike_prediction\venv\lib\site-packages\flask\app.py", line 1463, in wsgi_app
    response = self.full_dispatch_request()
  File "C:\project\bike_prediction\venv\lib\site-packages\flask\app.py", line 872, in full_dispatch_request
    rv = self.handle_user_exception(e)
  File "C:\project\bike_prediction\venv\lib\site-packages\flask\app.py", line 870, in full_dispatch_request
    rv = self.dispatch_request()
  File "C:\project\bike_prediction\venv\lib\site-packages\flask\app.py", line 855, in dispatch_request
    return self.ensure_sync(self.view_functions[rule.endpoint])(**view_args)  # type: ignore[no-any-return]
  File "app.py", line 34, in predict
    final_data = custom_data.get_data_as_dataframe()
  File "C:\project\bike_prediction\src\BikeSharePrediction\pipelines\prediction_pipeline.py", line 77, in get_data_as_dataframe
    logging.info('Exception Occured in prediction pipeline')
AttributeError: module 'src.BikeSharePrediction.logger.logging' has no attribute 'info'
[2024-03-28 12:32:09,750] 96 werkzeug - INFO - 127.0.0.1 - - [28/Mar/2024 12:32:09] "[35m[1mPOST /predict HTTP/1.1[0m" 500 -
